Workbook

Sheet Data
A1: Example | B1: Storage Usage in Mbit | C1: Entropy H | E1: Compression System | F1: Processes | G1: Compressed Size | H1: Average Code Word Length | J1: Links to Examples
A2: Wordnik | B2: 20.5 | C2: 4.25 | E2: Huffman | F2: 2565462 | G2: 11 | H2: 4.29 | J2: Wordnik | K2: https://raw.githubusercontent.com/wordnik/wordlist/refs/heads/main/wordlist-20210729.txt
A3: Shakespeare | B3: 44.6 | C3: 4.84 | E3: Shannon | F3: 2565500 | G3: 12 | H3: 4.7 | J3: Shakespeare | K3: https://gutenberg.org/cache/epub/100/pg100.txt
A4: alice29 | B4: 1.2 | C4: 4.57 | E4: Fano | F4: 2565349 | G4: 11.4 | H4: 4.44 | J4: Remaining... | K4: https://corpus.canterbury.ac.nz/descriptions/index.html
A5: asyoulik | B5: 1 | C5: 4.86 | E5: Comparison with Wordnik
A6: cp | B6: 0.2 | C6: 5.27
A7: fields | B7: 0.09 | C7: 5.05 | E7: Compression System | F7: Processes | G7: Compressed Size | H7: Average Code Word Length
A8: lcet10 | B8: 3.4 | C8: 4.67 | E8: Huffman | F8: 5575693 | G8: 27.2 | H8: 4.88
A9: plrabn12 | B9: 3.8 | C9: 4.58 | E9: Shannon | F9: 5576446 | G9: 29.6 | H9: 5.32
A10: e.coli | B10: 37.1 | C10: 2 | E10: Fano | F10: 5575268 | G10: 27.4 | H10: 4.91
A11: world192 | B11: 19.8 | C11: 5 | E11: Comparison with Shakespeare
A13: The number of processes is relative, different processes require a different amount of time and use different components, this number sould be interpreted vaguely. | E13: Compression System | F13: Processes | G13: Compressed Size | H13: Average Code Word Length
E14: Huffman | F14: 152529 | G14: 0.7 | H14: 4.61
E15: Shannon | F15: 152871 | G15: 0.8 | H15: 5.11
A16: Compression size does not include the storage space required for the compression scheme, the larger the data to be compressed the less statistically relevent this size gets, for simplicity we won't add this but for smaller examples you should remember this fact | E16: Fano | F16: 152236 | G16: 0.7 | H16: 4.67
E17: Comparison with alice29
E19: Compression System | F19: Processes | G19: Compressed Size | H19: Average Code Word Length
A20: For simplicity the storage usage for the examples are calculated by the number of characters multiplied by 8. This is comprable to the ASCII coded character set but mostly inacurate due to the fact most systems use UTF8 or UTF32 | E20: Huffman | F20: 129705 | G20: 0.6 | H20: 4.89
E21: Shannon | F21: 129947 | G21: 0.7 | H21: 5.33
E22: Fano | F22: 129432 | G22: 0.6 | H22: 4.92
E23: Comparison with asyoulik
E25: Compression System | F25: Processes | G25: Compressed Size | H25: Average Code Word Length
E26: Huffman | F26: 25735 | G26: 0.1 | H26: 5.31
E27: Shannon | F27: 26066 | G27: 0.1 | H27: 5.86
E28: Fano | F28: 25394 | G28: 0.1 | H28: 5.37
E29: Comparison with cp
E31: Compression System | F31: Processes | G31: Compressed Size | H31: Average Code Word Length
E32: Huffman | F32: 12123 | G32: 0.06 | H32: 5.09
E33: Shannon | F33: 12461 | G33: 0.06 | H33: 5.56
E34: Fano | F34: 11762 | G34: 0.06 | H34: 5.2
E35: Comparison with fields
E37: Compression System | F37: Processes | G37: Compressed Size | H37: Average Code Word Length
E38: Huffman | F38: 426969 | G38: 2 | H38: 4.7
E39: Shannon | F39: 427358 | G39: 2.2 | H39: 5.21
E40: Fano | F40: 426636 | G40: 2.1 | H40: 4.85
E41: Comparison with lcet10
E43: Compression System | F43: Processes | G43: Compressed Size | H43: Average Code Word Length
E44: Huffman | F44: 470950 | G44: 2.2 | H44: 4.61
E45: Shannon | F45: 471400 | G45: 2.4 | H45: 5.06
E46: Fano | F46: 470629 | G46: 2.2 | H46: 4.73
...

Sheet Plot
A1: Org.Storage to Avg Code Word Length | B1: fields | C1: cp | D1: asyoulik | E1: alice29 | F1: lcet10 | G1: plrabn12 | H1: world192 | I1: Wordnik | J1: e.coli | K1: Shakespeare
B2: =Data!B7 -> 0.09 | C2: =Data!B6 -> 0.2 | D2: =Data!B5 -> 1 | E2: =Data!B4 -> 1.2 | F2: =Data!B8 -> 3.4 | G2: =Data!B9 -> 3.8 | H2: =Data!B11 -> 19.8 | I2: =Data!B2 -> 20.5 | J2: =Data!B10 -> 37.1 | K2: =Data!B3 -> 44.6
A3: Huffman | B3: =Data!H32 -> 5.09 | C3: =Data!H26 -> 5.31 | D3: =Data!H20 -> 4.89 | E3: =Data!H14 -> 4.61 | F3: =Data!H38 -> 4.7 | G3: =Data!H44 -> 4.61 | H3: =Data!H56 -> 5.04 | I3: =Data!H2 -> 4.29 | J3: =Data!H50 -> 2 | K3: =Data!H8 -> 4.88
A4: Shannon | B4: =Data!H33 -> 5.56 | C4: =Data!H27 -> 5.86 | D4: =Data!H21 -> 5.33 | E4: =Data!H15 -> 5.11 | F4: =Data!H39 -> 5.21 | G4: =Data!H45 -> 5.06 | H4: =Data!H57 -> 5.51 | I4: =Data!H3 -> 4.7 | J4: =Data!H51 -> 2.49 | K4: =Data!H9 -> 5.32
A5: Fano | B5: =Data!H34 -> 5.2 | C5: =Data!H28 -> 5.37 | D5: =Data!H22 -> 4.92 | E5: =Data!H16 -> 4.67 | F5: =Data!H40 -> 4.85 | G5: =Data!H46 -> 4.73 | H5: =Data!H58 -> 5.09 | I5: =Data!H4 -> 4.44 | J5: =Data!H52 -> 2 | K5: =Data!H10 -> 4.91
A7: Entropy to Avg Code Word Length | B7: e.coli | C7: Wordnik | D7: alice29 | E7: plrabn12 | F7: lcet10 | G7: Shakespeare | H7: asyoulik | I7: world192 | J7: fields | K7: cp
B8: =Data!C10 -> 2 | C8: =Data!C2 -> 4.25 | D8: =Data!C4 -> 4.57 | E8: =Data!C9 -> 4.58 | F8: =Data!C8 -> 4.67 | G8: =Data!C3 -> 4.84 | H8: =Data!C5 -> 4.86 | I8: =Data!C11 -> 5 | J8: =Data!C7 -> 5.05 | K8: =Data!C6 -> 5.27
A9: Huffman | B9: =J3 -> 2 | C9: =I3 -> 4.29 | D9: =E3 -> 4.61 | E9: =G3 -> 4.61 | F9: =F3 -> 4.7 | G9: =K3 -> 4.88 | H9: =D3 -> 4.89 | I9: =H3 -> 5.04 | J9: =B3 -> 5.09 | K9: =C3 -> 5.31
A10: Shannon | B10: =J4 -> 2.49 | C10: =I4 -> 4.7 | D10: =E4 -> 5.11 | E10: =G4 -> 5.06 | F10: =F4 -> 5.21 | G10: =K4 -> 5.32 | H10: =D4 -> 5.33 | I10: =H4 -> 5.51 | J10: =B4 -> 5.56 | K10: =C4 -> 5.86
A11: Fano | B11: =J5 -> 2 | C11: =I5 -> 4.44 | D11: =E5 -> 4.67 | E11: =G5 -> 4.73 | F11: =F5 -> 4.85 | G11: =K5 -> 4.91 | H11: =D5 -> 4.92 | I11: =H5 -> 5.09 | J11: =B5 -> 5.2 | K11: =C5 -> 5.37
